<?xml version="1.0" ?>
<!-- =================================================================================== -->
<!-- |    This document was autogenerated by xacro from youbot4.urdf.xacro             | -->
<!-- |    EDITING THIS FILE BY HAND IS NOT RECOMMENDED                                 | -->
<!-- =================================================================================== -->
<!-- Revolute-Revolute Manipulator -->
<robot name="rrbot" xmlns:xacro="http://www.ros.org/wiki/xacro">
  <!-- damping coefficient -->
  <!-- Base Link -->
  <link name="base_link">
    <visual>
      <origin rpy="0 0 0" xyz="0 0 1.0"/>
      <geometry>
        <box size="0.1 0.1 2"/>
      </geometry>
    </visual>
  </link>
  <!-- Joint between Base Link and Middle Link -->
  <joint name="joint_base_mid" type="revolute">
    <parent link="base_link"/>
    <child link="mid_link"/>
    <origin rpy="0 0 0" xyz="0 0.1 1.95"/>
    <axis xyz="0 1 0"/>
    <dynamics damping="0.7"/>
    <limit effort="100.0" lower="-3.14" upper="3.14" velocity="0.5"/>
  </joint>
  <!-- Middle Link -->
  <link name="mid_link">
    <visual>
      <origin rpy="0 0 0" xyz="0 0 0.45"/>
      <geometry>
        <box size="0.1 0.1 1"/>
      </geometry>
    </visual>
  </link>
  <!-- Joint between Middle Link and Top Link -->
  <joint name="joint_mid_top" type="revolute">
    <parent link="mid_link"/>
    <child link="top_link"/>
    <origin rpy="0 0 0" xyz="0 0.1 0.9"/>
    <axis xyz="0 1 0"/>
    <dynamics damping="0.7"/>
    <limit effort="100.0" lower="-3.14" upper="3.14" velocity="0.5"/>
  </joint>
  <!-- Top Link -->
  <link name="top_link">
    <visual>
      <origin rpy="0 0 0" xyz="0 0 0.45"/>
      <geometry>
        <box size="0.1 0.1 1"/>
      </geometry>
    </visual>
  </link>
  <!-- youbotbase -->
  <link name="youbotbase">
    <visual>
      <origin rpy="0 0 0" xyz="0 0 0"/>
      <geometry>
        <box size="0.5 0.5 0.25"/>
      </geometry>
    </visual>
  </link>
  <joint name="joint_yuobotbase_baselink" type="revolute">
    <parent link="youbotbase"/>
    <child link="base_link"/>
    <origin rpy="0 0 0" xyz="0 0 0.125"/>
    <axis xyz="0 1 0"/>
    <dynamics damping="0.7"/>
    <limit effort="100.0" lower="-3.14" upper="3.14" velocity="0.5"/>
  </joint>
  <!-- Right Wheel -->
  <link name="right_wheel">
    <visual>
      <origin rpy="1.570795 0 0" xyz="0 0 0"/>
      <geometry>
        <cylinder length="0.1" radius="0.2"/>
      </geometry>
    </visual>
  </link>
  <joint name="joint_right_wheel" type="continuous">
    <parent link="youbotbase"/>
    <child link="right_wheel"/>
    <origin rpy="0 0 0" xyz="0 -0.30 0"/>
    <axis xyz="0 1 0"/>
  </joint>
  <!-- Left Wheel -->
  <link name="left_wheel">
    <visual>
      <origin rpy="1.570795 0 0" xyz="0 0 0"/>
      <geometry>
        <cylinder length="0.1" radius="0.2"/>
      </geometry>
    </visual>
  </link>
  <joint name="joint_left_wheel" type="continuous">
    <parent link="youbotbase"/>
    <child link="left_wheel"/>
    <origin rpy="0 0 0" xyz="0 0.30 0"/>
    <axis xyz="0 1 0"/>
  </joint>
  <link name="gripperdummy">
    <visual>
      <origin rpy="1.570795 0 0" xyz="0 0 0"/>
      <geometry>
        <sphere radius="0.02"/>
      </geometry>
    </visual>
  </link>
  <joint name="joint_gripper" type="continuous">
    <parent link="top_link"/>
    <child link="gripperdummy"/>
    <origin rpy="0 0 0" xyz="0 0 0.95"/>
    <axis xyz="0 1 0"/>
  </joint>
</robot>
