<?xml version="1.0" ?>
<!-- =================================================================================== -->
<!-- |    This document was autogenerated by xacro from youbot7.urdf.xacro             | -->
<!-- |    EDITING THIS FILE BY HAND IS NOT RECOMMENDED                                 | -->
<!-- =================================================================================== -->
<!-- Revolute-Revolute Manipulator -->
<robot name="rrbot" xmlns:xacro="http://www.ros.org/wiki/xacro">
  <!-- damping coefficient -->
  <!-- Base Link -->
  <link name="base_link">
    <visual>
      <origin rpy="0 0 0" xyz="0 0 1.0"/>
      <geometry>
        <box size="0.1 0.1 2"/>
      </geometry>
    </visual>
  </link>
  <!--  <joint name="joint_base_mid" type="revolute">-->
  <!--    <parent link="base_link"/>-->
  <!--    <child link="mid_link"/>-->
  <!--    <origin xyz="0 ${width} ${height1 - axle_offset}" rpy="0 0 0"/>-->
  <!--    <axis xyz="0 1 0"/>-->
  <!--    <dynamics damping="${damp}"/>-->
  <!--    <limit effort="100.0" velocity="0.5" lower="-3.14" upper="3.14" />-->
  <!--  </joint>-->
  <!--  <link name="mid_link">-->
  <!--    <visual>-->
  <!--      <origin xyz="0 0 ${height2/2 - axle_offset}" rpy="0 0 0"/>-->
  <!--      <geometry>-->
  <!--	<box size="${width} ${width} ${height2}"/>-->
  <!--      </geometry>-->
  <!--    </visual>-->
  <!--   </link>-->
  <!--  <joint name="joint_mid_top" type="revolute">-->
  <!--    <parent link="mid_link"/>-->
  <!--    <child link="top_link"/>-->
  <!--    <origin xyz="0 ${width} ${height2 - axle_offset*2}" rpy="0 0 0"/>-->
  <!--    <axis xyz="0 1 0"/>-->
  <!--    <dynamics damping="${damp}"/>-->
  <!--    <limit effort="100.0" velocity="0.5" lower="-3.14" upper="3.14" />-->
  <!--  </joint>-->
  <!--  <link name="top_link">-->
  <!--    <visual>-->
  <!--      <origin xyz="0 0 ${height3/2 - axle_offset}" rpy="0 0 0"/>-->
  <!--      <geometry>-->
  <!--	<box size="${width} ${width} ${height3}"/>-->
  <!--      </geometry>-->
  <!--    </visual>-->
  <!--    -->
  <!--  </link>-->
  <!-- youbotbase -->
  <link name="youbotbase">
    <visual>
      <origin rpy="0 0 0" xyz="0 0 0"/>
      <geometry>
        <box size="0.5 0.5 0.25"/>
      </geometry>
    </visual>
  </link>
  <joint name="joint_youbotbase_baselink" type="revolute">
    <parent link="youbotbase"/>
    <child link="base_link"/>
    <origin rpy="0 0 0" xyz="0 0 0.125"/>
    <axis xyz="0 1 0"/>
    <dynamics damping="0.7"/>
    <limit effort="100.0" lower="-3.14" upper="3.14" velocity="0.5"/>
  </joint>
  <!-- Right Wheel front-->
  <link name="right_wheel_front">
    <visual>
      <origin rpy="1.570795 0 0" xyz="0 0 0"/>
      <geometry>
        <cylinder length="0.1" radius="0.2"/>
      </geometry>
    </visual>
  </link>
  <joint name="joint_right_wheel_front" type="continuous">
    <parent link="youbotbase"/>
    <child link="right_wheel_front"/>
    <origin rpy="0 0 0" xyz="0.25 0.30 0"/>
    <axis xyz="0 1 0"/>
  </joint>
  <!-- Right Wheel back-->
  <link name="right_wheel_back">
    <visual>
      <origin rpy="1.570795 0 0" xyz="0 0 0"/>
      <geometry>
        <cylinder length="0.1" radius="0.2"/>
      </geometry>
    </visual>
  </link>
  <joint name="joint_right_wheel_back" type="continuous">
    <parent link="youbotbase"/>
    <child link="right_wheel_back"/>
    <origin rpy="0 0 0" xyz="-0.25 0.30 0"/>
    <axis xyz="0 1 0"/>
  </joint>
  <!-- Left Wheel front-->
  <link name="left_wheel_front">
    <visual>
      <origin rpy="1.570795 0 0" xyz="0 0 0"/>
      <geometry>
        <cylinder length="0.1" radius="0.2"/>
      </geometry>
    </visual>
  </link>
  <joint name="joint_left_wheel_front" type="continuous">
    <parent link="youbotbase"/>
    <child link="left_wheel_front"/>
    <origin rpy="0 0 0" xyz="0.25 -0.30 0"/>
    <axis xyz="0 1 0"/>
  </joint>
  <!-- Left Wheel back -->
  <link name="left_wheel_back">
    <visual>
      <origin rpy="1.570795 0 0" xyz="0 0 0"/>
      <geometry>
        <cylinder length="0.1" radius="0.2"/>
      </geometry>
    </visual>
  </link>
  <joint name="joint_left_wheel_back" type="continuous">
    <parent link="youbotbase"/>
    <child link="left_wheel_back"/>
    <origin rpy="0 0 0" xyz="-0.25 -0.30 0"/>
    <axis xyz="0 1 0"/>
  </joint>
  <!--  <link name="gripperdummy">-->
  <!--    <visual>-->
  <!--      <origin xyz="0 0 0" rpy="1.570795 0 0" />-->
  <!--      <geometry>-->
  <!--          <sphere radius="0.02"/>-->
  <!--      </geometry>-->
  <!--    </visual>-->
  <!--  </link>-->
  <!--  <joint name="joint_gripper" type="continuous">-->
  <!--    <parent link="top_link"/>-->
  <!--    <child link="gripperdummy"/>-->
  <!--    <origin xyz="0 0 ${height3 - axle_offset}" rpy="0 0 0" /> -->
  <!--    <axis xyz="0 1 0" />-->
  <!--  </joint>-->
</robot>
