<?xml version="1.0" ?>
<!-- =================================================================================== -->
<!-- |    This document was autogenerated by xacro from youbot3.urdf.xacro             | -->
<!-- |    EDITING THIS FILE BY HAND IS NOT RECOMMENDED                                 | -->
<!-- =================================================================================== -->
<robot name="dd_robot">
  <!-- Base Link -->
  <link name="base_link">
    <visual>
      <origin rpy="0 0 0" xyz="0 0 0"/>
      <geometry>
        <box size="0.5 0.5 0.25"/>
      </geometry>
    </visual>
  </link>
  <!-- Right Wheel -->
  <link name="right_wheel">
    <visual>
      <origin rpy="1.570795 0 0" xyz="0 0 0"/>
      <geometry>
        <cylinder length="0.1" radius="0.2"/>
      </geometry>
    </visual>
  </link>
  <joint name="joint_right_wheel" type="continuous">
    <parent link="base_link"/>
    <child link="right_wheel"/>
    <origin rpy="0 0 0" xyz="0 -0.30 0"/>
    <axis xyz="0 1 0"/>
  </joint>
  <!-- Left Wheel -->
  <link name="left_wheel">
    <visual>
      <origin rpy="1.570795 0 0" xyz="0 0 0"/>
      <geometry>
        <cylinder length="0.1" radius="0.2"/>
      </geometry>
    </visual>
  </link>
  <joint name="joint_left_wheel" type="continuous">
    <parent link="base_link"/>
    <child link="left_wheel"/>
    <origin rpy="0 0 0" xyz="0 0.30 0"/>
    <axis xyz="0 1 0"/>
  </joint>
  <!-- First Link -->
  <link name="first_link">
    <visual>
      <origin rpy="0 0 0" xyz="0 0 0.5"/>
      <!--0.5=height/2 -->
      <geometry>
        <box size="0.1 0.1 1"/>
        <!-- height=1, base is a square -->
      </geometry>
    </visual>
  </link>
  <!-- Joint between first Link and base Link -->
  <joint name="joint_fir_base" type="revolute">
    <parent link="base_link"/>
    <child link="first_link"/>
    <origin rpy="0 0 0" xyz="0 0 0.05"/>
    <!--axle_offset=0.05, so the z is at (height-axle_offset)-->
    <axis xyz="0 1 0"/>
    <dynamics damping="0.7"/>
    <limit effort="100.0" lower="-1.57" upper="1.57" velocity="0.5"/>
  </joint>
  <!-- Middle Link -->
  <link name="mid_link">
    <visual>
      <origin rpy="0 0 0" xyz="0 0 0.95"/>
      <geometry>
        <box size="0.1 0.1 1"/>
        <!-- height=1, base is a square -->
      </geometry>
    </visual>
  </link>
  <!-- Joint between First Link and Middle Link -->
  <joint name="joint_fir_mid" type="revolute">
    <parent link="first_link"/>
    <child link="mid_link"/>
    <origin rpy="0 0 0" xyz="0 0.1 0.95"/>
    <axis xyz="0 1 0"/>
    <dynamics damping="0.7"/>
    <limit effort="100.0" lower="-3.14" upper="3.14" velocity="0.5"/>
  </joint>
</robot>
